<?xml version="1.0" encoding="utf-8"?>
<!-- This URDF was automatically created by SolidWorks to URDF Exporter! Originally created by Stephen Brawner (brawner@gmail.com) 
     Commit Version: 1.5.1-0-g916b5db  Build Version: 1.5.7152.31018
     For more information, please see http://wiki.ros.org/sw_urdf_exporter -->
<robot
  name="blattoidea">
  <link
    name="base_link">
    <inertial>
      <origin
        xyz="-0.0032562 -0.069209 -5.5511E-16"
        rpy="0 0 0" />
      <mass
        value="8.7926" />
      <inertia
        ixx="0.073403"
        ixy="3.695E-16"
        ixz="-5.5511E-17"
        iyy="0.17579"
        iyz="-4.7358E-16"
        izz="0.10293" />
    </inertial>
    <visual>
      <origin
        xyz="0 0 0"
        rpy="0 0 0" />
      <geometry>
        <mesh
          filename="package://blattoidea/meshes/base_link.STL" />
      </geometry>
      <material
        name="">
        <color
          rgba="0.89804 0.91765 0.92941 1" />
      </material>
    </visual>
    <collision>
      <origin
        xyz="0 0 0"
        rpy="0 0 0" />
      <geometry>
        <mesh
          filename="package://blattoidea/meshes/base_link.STL" />
      </geometry>
    </collision>
  </link>
  <link
    name="lw_Link">
    <inertial>
      <origin
        xyz="0.1137 -7.3413E-09 -7.3213E-06"
        rpy="0 0 0" />
      <mass
        value="0.97717" />
      <inertia
        ixx="0.0027567"
        ixy="-1.3395E-10"
        ixz="-3.9115E-07"
        iyy="0.0016171"
        iyz="-1.4519E-10"
        izz="0.0016171" />
    </inertial>
    <visual>
      <origin
        xyz="0 0 0"
        rpy="0 0 0" />
      <geometry>
        <mesh
          filename="package://blattoidea/meshes/lw_Link.STL" />
      </geometry>
      <material
        name="">
        <color
          rgba="1 1 1 1" />
      </material>
    </visual>
    <collision>
      <origin
        xyz="0 0 0"
        rpy="0 0 0" />
      <geometry>
        <mesh
          filename="package://blattoidea/meshes/lw_Link.STL" />
      </geometry>
    </collision>
  </link>
  <joint
    name="lw_joint"
    type="continuous">
    <origin
      xyz="-0.17114 -0.002 -0.089756"
      rpy="-2.9986 1.5708 -1.6213" />
    <parent
      link="base_link" />
    <child
      link="lw_Link" />
    <axis
      xyz="1 0 0" />
  </joint>
  <link
    name="rw_Link">
    <inertial>
      <origin
        xyz="0.11204 3.2035E-08 -7.2607E-06"
        rpy="0 0 0" />
      <mass
        value="0.97717" />
      <inertia
        ixx="0.0027567"
        ixy="1.5968E-10"
        ixz="-3.9099E-07"
        iyy="0.0016171"
        iyz="-1.7526E-11"
        izz="0.0016171" />
    </inertial>
    <visual>
      <origin
        xyz="0 0 0"
        rpy="0 0 0" />
      <geometry>
        <mesh
          filename="package://blattoidea/meshes/rw_Link.STL" />
      </geometry>
      <material
        name="">
        <color
          rgba="1 1 1 1" />
      </material>
    </visual>
    <collision>
      <origin
        xyz="0 0 0"
        rpy="0 0 0" />
      <geometry>
        <mesh
          filename="package://blattoidea/meshes/rw_Link.STL" />
      </geometry>
    </collision>
  </link>
  <joint
    name="rw_joint"
    type="continuous">
    <origin
      xyz="-0.17114 -0.002 0.091417"
      rpy="3.076 -1.5708 0" />
    <parent
      link="base_link" />
    <child
      link="rw_Link" />
    <axis
      xyz="1 0 0" />
  </joint>
  <link
    name="rc_segment_Link">
    <inertial>
      <origin
        xyz="-0.002 0.050703 -0.022367"
        rpy="0 0 0" />
      <mass
        value="0.045681" />
      <inertia
        ixx="1.6937E-05"
        ixy="-2.6165E-08"
        ixz="4.9734E-07"
        iyy="2.8421E-05"
        iyz="8.692E-07"
        izz="1.1945E-05" />
    </inertial>
    <visual>
      <origin
        xyz="0 0 0"
        rpy="0 0 0" />
      <geometry>
        <mesh
          filename="package://blattoidea/meshes/rc_segment_Link.STL" />
      </geometry>
      <material
        name="">
        <color
          rgba="0.89804 0.91765 0.92941 1" />
      </material>
    </visual>
    <collision>
      <origin
        xyz="0 0 0"
        rpy="0 0 0" />
      <geometry>
        <mesh
          filename="package://blattoidea/meshes/rc_segment_Link.STL" />
      </geometry>
    </collision>
  </link>
  <joint
    name="rc_segment_joint"
    type="fixed">
    <origin
      xyz="0.13468 0.053 0.13557"
      rpy="3.089 1.4732 0" />
    <parent
      link="base_link" />
    <child
      link="rc_segment_Link" />
    <axis
      xyz="0 0 0" />
  </joint>
  <link
    name="r_caster_Link">
    <inertial>
      <origin
        xyz="-1.72780524609895E-08 0.0301166030645037 0.0154473150358126"
        rpy="0 0 0" />
      <mass
        value="0.0264605676973988" />
      <inertia
        ixx="1.1218008627058E-05"
        ixy="1.76900336284862E-11"
        ixz="-1.02095407709023E-11"
        iyy="9.11781675355718E-06"
        iyz="2.51889243789533E-06"
        izz="1.08616569515216E-05" />
    </inertial>
    <visual>
      <origin
        xyz="0 0 0"
        rpy="0 0 0" />
      <geometry>
        <mesh
          filename="package://blattoidea/meshes/r_caster_Link.STL" />
      </geometry>
      <material
        name="">
        <color
          rgba="0.898039215686275 0.917647058823529 0.929411764705882 1" />
      </material>
    </visual>
    <collision>
      <origin
        xyz="0 0 0"
        rpy="0 0 0" />
      <geometry>
        <mesh
          filename="package://blattoidea/meshes/r_caster_Link.STL" />
      </geometry>
    </collision>
  </link>
  <joint
    name="r_caster_joint"
    type="continuous">
    <origin
      xyz="-0.002 0.0013134 -0.024965"
      rpy="3.0363 -0.090647 -3.1368" />
    <parent
      link="rc_segment_Link" />
    <child
      link="r_caster_Link" />
    <axis
      xyz="0 1 0" />
  </joint>
  <link
    name="rc_wheel_Link">
    <inertial>
      <origin
        xyz="-3.28070903776734E-14 -7.88258347483861E-15 2.44249065417534E-15"
        rpy="0 0 0" />
      <mass
        value="0.0498995656286702" />
      <inertia
        ixx="3.54082696398041E-05"
        ixy="-1.96935160236625E-20"
        ixz="5.0821976835258E-20"
        iyy="1.84620775423208E-05"
        iyz="3.3881317890172E-21"
        izz="1.84620775423208E-05" />
    </inertial>
    <visual>
      <origin
        xyz="0 0 0"
        rpy="0 0 0" />
      <geometry>
        <mesh
          filename="package://blattoidea/meshes/rc_wheel_Link.STL" />
      </geometry>
      <material
        name="">
        <color
          rgba="1 1 1 1" />
      </material>
    </visual>
    <collision>
      <origin
        xyz="0 0 0"
        rpy="0 0 0" />
      <geometry>
        <mesh
          filename="package://blattoidea/meshes/rc_wheel_Link.STL" />
      </geometry>
    </collision>
  </link>
  <joint
    name="rc_wheel_joint"
    type="continuous">
    <origin
      xyz="0 -0.0013134 0.024965"
      rpy="0.1671 0 -3.1416" />
    <parent
      link="r_caster_Link" />
    <child
      link="rc_wheel_Link" />
    <axis
      xyz="1 0 0" />
  </joint>
  <link
    name="lc_segment_Link">
    <inertial>
      <origin
        xyz="0 0 0"
        rpy="0 0 0" />
      <mass
        value="0" />
      <inertia
        ixx="0"
        ixy="0"
        ixz="0"
        iyy="0"
        iyz="0"
        izz="0" />
    </inertial>
    <visual>
      <origin
        xyz="0 0 0"
        rpy="0 0 0" />
      <geometry>
        <mesh
          filename="package://blattoidea/meshes/lc_segment_Link.STL" />
      </geometry>
      <material
        name="">
        <color
          rgba="1 1 1 1" />
      </material>
    </visual>
    <collision>
      <origin
        xyz="0 0 0"
        rpy="0 0 0" />
      <geometry>
        <mesh
          filename="package://blattoidea/meshes/lc_segment_Link.STL" />
      </geometry>
    </collision>
  </link>
  <joint
    name="lc_segment_joint"
    type="fixed">
    <origin
      xyz="0.18405 0.053 -0.13557"
      rpy="-0.052561 -1.4732 3.1416" />
    <parent
      link="base_link" />
    <child
      link="lc_segment_Link" />
    <axis
      xyz="0 0 0" />
  </joint>
  <link
    name="l_caster_Link">
    <inertial>
      <origin
        xyz="-1.21895196159016E-08 0.0301166124330257 0.0154473134055489"
        rpy="0 0 0" />
      <mass
        value="0.0264605807216404" />
      <inertia
        ixx="1.1218016691202E-05"
        ixy="4.20280335236751E-12"
        ixz="-6.32664658405435E-13"
        iyy="9.11781751607426E-06"
        iyz="2.51889701537358E-06"
        izz="1.08616612913165E-05" />
    </inertial>
    <visual>
      <origin
        xyz="0 0 0"
        rpy="0 0 0" />
      <geometry>
        <mesh
          filename="package://blattoidea/meshes/l_caster_Link.STL" />
      </geometry>
      <material
        name="">
        <color
          rgba="0.898039215686275 0.917647058823529 0.929411764705882 1" />
      </material>
    </visual>
    <collision>
      <origin
        xyz="0 0 0"
        rpy="0 0 0" />
      <geometry>
        <mesh
          filename="package://blattoidea/meshes/l_caster_Link.STL" />
      </geometry>
    </collision>
  </link>
  <joint
    name="l_caster_joint"
    type="continuous">
    <origin
      xyz="-0.002 0.0013134 -0.024965"
      rpy="0.014242 -0.66482 -0.041251" />
    <parent
      link="lc_segment_Link" />
    <child
      link="l_caster_Link" />
    <axis
      xyz="0 1 0" />
  </joint>
  <link
    name="lc_wheel_Link">
    <inertial>
      <origin
        xyz="-4.3743E-14 9.3259E-15 -4.0523E-15"
        rpy="0 0 0" />
      <mass
        value="0.0499" />
      <inertia
        ixx="3.5408E-05"
        ixy="-1.3096E-20"
        ixz="9.1056E-21"
        iyy="1.8462E-05"
        iyz="-1.0588E-21"
        izz="1.8462E-05" />
    </inertial>
    <visual>
      <origin
        xyz="0 0 0"
        rpy="0 0 0" />
      <geometry>
        <mesh
          filename="package://blattoidea/meshes/lc_wheel_Link.STL" />
      </geometry>
      <material
        name="">
        <color
          rgba="1 1 1 1" />
      </material>
    </visual>
    <collision>
      <origin
        xyz="0 0 0"
        rpy="0 0 0" />
      <geometry>
        <mesh
          filename="package://blattoidea/meshes/lc_wheel_Link.STL" />
      </geometry>
    </collision>
  </link>
  <joint
    name="lc_wheel_joint"
    type="continuous">
    <origin
      xyz="0 -0.0013134 0.024965"
      rpy="-2.8657 0 -3.1416" />
    <parent
      link="l_caster_Link" />
    <child
      link="lc_wheel_Link" />
    <axis
      xyz="-1 0 0" />
  </joint>
</robot>