<?xml version="1.0" encoding="utf-8"?>
<!-- This URDF was automatically created by SolidWorks to URDF Exporter! Originally created by Stephen Brawner (brawner@gmail.com) 
     Commit Version: 1.5.1-0-g916b5db  Build Version: 1.5.7152.31018
     For more information, please see http://wiki.ros.org/sw_urdf_exporter -->
<robot
  name="blattoidea">
  <link
    name="base_link">
    <inertial>
      <origin
        xyz="0.00325619311123409 -2.23039142970567E-14 0.0692086370036087"
        rpy="0 0 0" />
      <mass
        value="8.79255713417749" />
      <inertia
        ixx="0.0734027658932192"
        ixy="-2.76280505697937E-16"
        ixz="-1.07846523034601E-16"
        iyy="0.102931710777646"
        iyz="-2.50856151514765E-15"
        izz="0.175786526057808" />
    </inertial>
    <visual>
      <origin
        xyz="0 0 0"
        rpy="0 0 0" />
      <geometry>
        <mesh
          filename="package://blattoidea/meshes/base_link.STL" />
      </geometry>
      <material
        name="">
        <color
          rgba="0.898039215686275 0.917647058823529 0.929411764705882 1" />
      </material>
    </visual>
    <collision>
      <origin
        xyz="0 0 0"
        rpy="0 0 0" />
      <geometry>
        <mesh
          filename="package://blattoidea/meshes/base_link.STL" />
      </geometry>
    </collision>
  </link>
  <link
    name="lw_Link">
    <inertial>
      <origin
        xyz="0.0808553485818156 -8.93504020771374E-14 -7.28085555834479E-06"
        rpy="0 0 0" />
      <mass
        value="0.977168759094327" />
      <inertia
        ixx="0.00275674165352189"
        ixy="-1.03502289371494E-14"
        ixz="-3.90983752277037E-07"
        iyy="0.00161704630212876"
        iyz="4.59411554425522E-16"
        izz="0.00161708194376393" />
    </inertial>
    <visual>
      <origin
        xyz="0 0 0"
        rpy="0 0 0" />
      <geometry>
        <mesh
          filename="package://blattoidea/meshes/lw_Link.STL" />
      </geometry>
      <material
        name="">
        <color
          rgba="1 1 1 1" />
      </material>
    </visual>
    <collision>
      <origin
        xyz="0 0 0"
        rpy="0 0 0" />
      <geometry>
        <mesh
          filename="package://blattoidea/meshes/lw_Link.STL" />
      </geometry>
    </collision>
  </link>
  <joint
    name="lw_joint"
    type="continuous">
    <origin
      xyz="0.17114 0.1226 0.002"
      rpy="-1.5708 0 1.5708" />
    <parent
      link="base_link" />
    <child
      link="lw_Link" />
    <axis
      xyz="1 0 0" />
  </joint>
  <link
    name="rw_Link">
    <inertial>
      <origin
        xyz="0.0808553485818126 -5.82923466441176E-14 -7.28085556619962E-06"
        rpy="0 0 0" />
      <mass
        value="0.977168759094327" />
      <inertia
        ixx="0.00275674165352189"
        ixy="-1.03504114825236E-14"
        ixz="-3.90983752276569E-07"
        iyy="0.00161704630212876"
        iyz="4.57646248429487E-16"
        izz="0.00161708194376393" />
    </inertial>
    <visual>
      <origin
        xyz="0 0 0"
        rpy="0 0 0" />
      <geometry>
        <mesh
          filename="package://blattoidea/meshes/rw_Link.STL" />
      </geometry>
      <material
        name="">
        <color
          rgba="1 1 1 1" />
      </material>
    </visual>
    <collision>
      <origin
        xyz="0 0 0"
        rpy="0 0 0" />
      <geometry>
        <mesh
          filename="package://blattoidea/meshes/rw_Link.STL" />
      </geometry>
    </collision>
  </link>
  <joint
    name="rw_joint"
    type="continuous">
    <origin
      xyz="0.17114 -0.1226 0.002"
      rpy="1.5708 0 -1.5708" />
    <parent
      link="base_link" />
    <child
      link="rw_Link" />
    <axis
      xyz="1 0 0" />
  </joint>
  <link
    name="rc_segment_Link">
    <inertial>
      <origin
        xyz="-0.00199999999999995 0.0507028605154133 -0.0223671012384332"
        rpy="0 0 0" />
      <mass
        value="0.0456806083099006" />
      <inertia
        ixx="1.69365480799051E-05"
        ixy="-2.61652032862409E-08"
        ixz="4.97343727280345E-07"
        iyy="2.84210040220917E-05"
        iyz="8.69198280165372E-07"
        izz="1.19451595992085E-05" />
    </inertial>
    <visual>
      <origin
        xyz="0 0 0"
        rpy="0 0 0" />
      <geometry>
        <mesh
          filename="package://blattoidea/meshes/rc_segment_Link.STL" />
      </geometry>
      <material
        name="">
        <color
          rgba="0.898039215686275 0.917647058823529 0.929411764705882 1" />
      </material>
    </visual>
    <collision>
      <origin
        xyz="0 0 0"
        rpy="0 0 0" />
      <geometry>
        <mesh
          filename="package://blattoidea/meshes/rc_segment_Link.STL" />
      </geometry>
    </collision>
  </link>
  <joint
    name="rc_segment_joint"
    type="fixed">
    <origin
      xyz="-0.13468 -0.13557 -0.053"
      rpy="1.5182 0 1.6684" />
    <parent
      link="base_link" />
    <child
      link="rc_segment_Link" />
    <axis
      xyz="0 0 0" />
  </joint>
  <link
    name="r_caster_Link">
    <inertial>
      <origin
        xyz="-1.88672009127089E-08 0.0301165962341548 0.0154473114257098"
        rpy="0 0 0" />
      <mass
        value="0.0264605949467884" />
      <inertia
        ixx="1.12179776898766E-05"
        ixy="3.2755877336865E-12"
        ixz="-1.14314616853686E-12"
        iyy="9.11782185184723E-06"
        iyz="2.51887439877833E-06"
        izz="1.08616620506511E-05" />
    </inertial>
    <visual>
      <origin
        xyz="0 0 0"
        rpy="0 0 0" />
      <geometry>
        <mesh
          filename="package://blattoidea/meshes/r_caster_Link.STL" />
      </geometry>
      <material
        name="">
        <color
          rgba="0.898039215686275 0.917647058823529 0.929411764705882 1" />
      </material>
    </visual>
    <collision>
      <origin
        xyz="0 0 0"
        rpy="0 0 0" />
      <geometry>
        <mesh
          filename="package://blattoidea/meshes/r_caster_Link.STL" />
      </geometry>
    </collision>
  </link>
  <joint
    name="r_caster_joint"
    type="continuous">
    <origin
      xyz="-0.002 0.0013134 -0.024965"
      rpy="3.0362 0.097478 3.1364" />
    <parent
      link="rc_segment_Link" />
    <child
      link="r_caster_Link" />
    <axis
      xyz="0 0.99862 0.052537" />
  </joint>
  <link
    name="rc_wheel_Link">
    <inertial>
      <origin
        xyz="1.85407245112401E-14 -3.22103455019374E-14 7.27196081129478E-15"
        rpy="0 0 0" />
      <mass
        value="0.0498995656286701" />
      <inertia
        ixx="3.54082696398039E-05"
        ixy="-4.40748213728033E-23"
        ixz="-3.9926883710541E-23"
        iyy="1.84620775423207E-05"
        iyz="-1.65602536623508E-21"
        izz="1.84620775423207E-05" />
    </inertial>
    <visual>
      <origin
        xyz="0 0 0"
        rpy="0 0 0" />
      <geometry>
        <mesh
          filename="package://blattoidea/meshes/rc_wheel_Link.STL" />
      </geometry>
      <material
        name="">
        <color
          rgba="1 1 1 1" />
      </material>
    </visual>
    <collision>
      <origin
        xyz="0 0 0"
        rpy="0 0 0" />
      <geometry>
        <mesh
          filename="package://blattoidea/meshes/rc_wheel_Link.STL" />
      </geometry>
    </collision>
  </link>
  <joint
    name="rc_wheel_joint"
    type="continuous">
    <origin
      xyz="0 -0.0013134 0.024965"
      rpy="-0.052561 0 3.1416" />
    <parent
      link="r_caster_Link" />
    <child
      link="rc_wheel_Link" />
    <axis
      xyz="1 0 0" />
  </joint>
  <link
    name="lc_segment_Link">
    <inertial>
      <origin
        xyz="-0.00199999999996911 0.0507028605154356 -0.0223671012384291"
        rpy="0 0 0" />
      <mass
        value="0.0456806083099005" />
      <inertia
        ixx="1.69365480799051E-05"
        ixy="-2.61652032862427E-08"
        ixz="4.97343727280348E-07"
        iyy="2.84210040220916E-05"
        iyz="8.69198280165364E-07"
        izz="1.19451595992085E-05" />
    </inertial>
    <visual>
      <origin
        xyz="0 0 0"
        rpy="0 0 0" />
      <geometry>
        <mesh
          filename="package://blattoidea/meshes/lc_segment_Link.STL" />
      </geometry>
      <material
        name="">
        <color
          rgba="0.898039215686275 0.917647058823529 0.929411764705882 1" />
      </material>
    </visual>
    <collision>
      <origin
        xyz="0 0 0"
        rpy="0 0 0" />
      <geometry>
        <mesh
          filename="package://blattoidea/meshes/lc_segment_Link.STL" />
      </geometry>
    </collision>
  </link>
  <joint
    name="lc_segment_joint"
    type="fixed">
    <origin
      xyz="-0.18405 0.13557 -0.053"
      rpy="1.5182 0 -1.4732" />
    <parent
      link="base_link" />
    <child
      link="lc_segment_Link" />
    <axis
      xyz="0 0 0" />
  </joint>
  <link
    name="l_caster_Link">
    <inertial>
      <origin
        xyz="-1.88672001633083E-08 0.030116596234179 0.0154473114256789"
        rpy="0 0 0" />
      <mass
        value="0.0264605949467887" />
      <inertia
        ixx="1.12179776898766E-05"
        ixy="3.27558774750597E-12"
        ixz="-1.14314612088057E-12"
        iyy="9.11782185184734E-06"
        iyz="2.51887439877833E-06"
        izz="1.0861662050651E-05" />
    </inertial>
    <visual>
      <origin
        xyz="0 0 0"
        rpy="0 0 0" />
      <geometry>
        <mesh
          filename="package://blattoidea/meshes/l_caster_Link.STL" />
      </geometry>
      <material
        name="">
        <color
          rgba="0.898039215686275 0.917647058823529 0.929411764705882 1" />
      </material>
    </visual>
    <collision>
      <origin
        xyz="0 0 0"
        rpy="0 0 0" />
      <geometry>
        <mesh
          filename="package://blattoidea/meshes/l_caster_Link.STL" />
      </geometry>
    </collision>
  </link>
  <joint
    name="l_caster_joint"
    type="continuous">
    <origin
      xyz="-0.002 0.0013134 -0.024965"
      rpy="0.00025094 -0.097478 -0.0051446" />
    <parent
      link="lc_segment_Link" />
    <child
      link="l_caster_Link" />
    <axis
      xyz="0 0.99862 0.052537" />
  </joint>
  <link
    name="lc_wheel_Link">
    <inertial>
      <origin
        xyz="1.79301018476963E-14 1.6826817716975E-14 -3.02535774210355E-15"
        rpy="0 0 0" />
      <mass
        value="0.0498995656286702" />
      <inertia
        ixx="3.5408269639804E-05"
        ixy="5.18772505873196E-22"
        ixz="-9.91489083238259E-22"
        iyy="1.84620775423207E-05"
        iyz="2.30363884891597E-21"
        izz="1.84620775423207E-05" />
    </inertial>
    <visual>
      <origin
        xyz="0 0 0"
        rpy="0 0 0" />
      <geometry>
        <mesh
          filename="package://blattoidea/meshes/lc_wheel_Link.STL" />
      </geometry>
      <material
        name="">
        <color
          rgba="1 1 1 1" />
      </material>
    </visual>
    <collision>
      <origin
        xyz="0 0 0"
        rpy="0 0 0" />
      <geometry>
        <mesh
          filename="package://blattoidea/meshes/lc_wheel_Link.STL" />
      </geometry>
    </collision>
  </link>
  <joint
    name="lc_wheel_joint"
    type="continuous">
    <origin
      xyz="0 -0.0013134 0.024965"
      rpy="3.089 0 3.1416" />
    <parent
      link="l_caster_Link" />
    <child
      link="lc_wheel_Link" />
    <axis
      xyz="-1 0 0" />
  </joint>
</robot>