<?xml version="1.0" encoding="utf-8"?>
<!-- This URDF was automatically created by SolidWorks to URDF Exporter! Originally created by Stephen Brawner (brawner@gmail.com) 
     Commit Version: 1.5.1-0-g916b5db  Build Version: 1.5.7152.31018
     For more information, please see http://wiki.ros.org/sw_urdf_exporter -->
<robot
  name="blattoidea">

	<link name="base_footprint">
	</link>
  
  <link
    name="base_link">
    <inertial>
      <origin
        xyz="0.00325619311123183 -2.68724627668802E-14 0.069208637003638"
        rpy="0 0 0" />
      <mass
        value="8.79255713417749" />
      <inertia
        ixx="0.0734027658932193"
        ixy="-2.76407451456962E-16"
        ixz="-1.07879396168151E-16"
        iyy="0.102931710777646"
        iyz="-2.50854574138517E-15"
        izz="0.175786526057808" />
    </inertial>
    <visual>
      <origin
        xyz="0 0 0"
        rpy="0 0 0" />
      <geometry>
        <mesh
          filename="package://blattoidea/meshes/base_link.STL" />
      </geometry>
      <material
        name="">
        <color
          rgba="0.898039215686275 0.917647058823529 0.929411764705882 1" />
      </material>
    </visual>
    <collision>
      <origin
        xyz="0 0 0"
        rpy="0 0 0" />
      <geometry>
        <mesh
          filename="package://blattoidea/meshes/base_link.STL" />
      </geometry>
    </collision>
  </link>
  <link
    name="lw_Link">
    <inertial>
      <origin
        xyz="0.0808553485818156 -1.29938594606305E-13 -7.28085555837255E-06"
        rpy="0 0 0" />
      <mass
        value="0.977168759094327" />
      <inertia
        ixx="0.00275674165352189"
        ixy="-1.03507576255232E-14"
        ixz="-3.90983752277197E-07"
        iyy="0.00161704630212875"
        iyz="4.59436432634313E-16"
        izz="0.00161708194376393" />
    </inertial>
    <visual>
      <origin
        xyz="0 0 0"
        rpy="0 0 0" />
      <geometry>
        <mesh
          filename="package://blattoidea/meshes/lw_Link.STL" />
      </geometry>
      <material
        name="">
        <color
          rgba="1 1 1 1" />
      </material>
    </visual>
    <collision>
      <origin
        xyz="0 0 0"
        rpy="0 0 0" />
      <geometry>
        <mesh
          filename="package://blattoidea/meshes/lw_Link.STL" />
      </geometry>
    </collision>
  </link>
  
	<joint name="base_footprint_base_link_joint" type="fixed">
		<origin xyz="0 0 -15"/>
		<parent link="base_footprint"/>
		<child link="base_link"/>
	</joint>
  
  <joint
    name="lw_joint"
    type="continuous">
    <origin
      xyz="0.171136704119859 0.122599999999968 0.00200000000000291"
      rpy="-1.5707963267949 0 1.5707963267949" />
    <parent
      link="base_link" />
    <child
      link="lw_Link" />
    <axis
      xyz="1 0 0" />
  </joint>
  <link
    name="rw_Link">
    <inertial>
      <origin
        xyz="0.0808553485818126 -1.9973606102397E-14 -7.28085556619962E-06"
        rpy="0 0 0" />
      <mass
        value="0.977168759094326" />
      <inertia
        ixx="0.00275674165352189"
        ixy="-1.03497032811902E-14"
        ixz="-3.909837522766E-07"
        iyy="0.00161704630212875"
        iyz="4.57357843709215E-16"
        izz="0.00161708194376393" />
    </inertial>
    <visual>
      <origin
        xyz="0 0 0"
        rpy="0 0 0" />
      <geometry>
        <mesh
          filename="package://blattoidea/meshes/rw_Link.STL" />
      </geometry>
      <material
        name="">
        <color
          rgba="1 1 1 1" />
      </material>
    </visual>
    <collision>
      <origin
        xyz="0 0 0"
        rpy="0 0 0" />
      <geometry>
        <mesh
          filename="package://blattoidea/meshes/rw_Link.STL" />
      </geometry>
    </collision>
  </link>
  <joint
    name="rw_joint"
    type="continuous">
    <origin
      xyz="0.171136704119851 -0.122600000000032 0.00199999999999654"
      rpy="1.5707963267949 0 -1.5707963267949" />
    <parent
      link="base_link" />
    <child
      link="rw_Link" />
    <axis
      xyz="-1 0 0" />
  </joint>
  <link
    name="rc_segment_Link">
    <inertial>
      <origin
        xyz="-0.00199999999999995 0.0507028605154515 -0.0223671012384312"
        rpy="0 0 0" />
      <mass
        value="0.0456806083099006" />
      <inertia
        ixx="1.69365480799051E-05"
        ixy="-2.61652032862409E-08"
        ixz="4.97343727280345E-07"
        iyy="2.84210040220917E-05"
        iyz="8.69198280165373E-07"
        izz="1.19451595992085E-05" />
    </inertial>
    <visual>
      <origin
        xyz="0 0 0"
        rpy="0 0 0" />
      <geometry>
        <mesh
          filename="package://blattoidea/meshes/rc_segment_Link.STL" />
      </geometry>
      <material
        name="">
        <color
          rgba="0.898039215686275 0.917647058823529 0.929411764705882 1" />
      </material>
    </visual>
    <collision>
      <origin
        xyz="0 0 0"
        rpy="0 0 0" />
      <geometry>
        <mesh
          filename="package://blattoidea/meshes/rc_segment_Link.STL" />
      </geometry>
    </collision>
  </link>
  <joint
    name="rc_segment_joint"
    type="fixed">
    <origin
      xyz="-0.134677221305586 -0.13557306854595 -0.0529999999999956"
      rpy="1.51823488521493 0 1.66840935514672" />
    <parent
      link="base_link" />
    <child
      link="rc_segment_Link" />
    <axis
      xyz="0 0 0" />
  </joint>
  <link
    name="r_caster_Link">
    <inertial>
      <origin
        xyz="-1.88672009127089E-08 0.0301165962341867 0.0154473114257115"
        rpy="0 0 0" />
      <mass
        value="0.0264605949467884" />
      <inertia
        ixx="1.12179776898766E-05"
        ixy="3.27558773113359E-12"
        ixz="-1.14314616958156E-12"
        iyy="9.11782185184723E-06"
        iyz="2.51887439877834E-06"
        izz="1.0861662050651E-05" />
    </inertial>
    <visual>
      <origin
        xyz="0 0 0"
        rpy="0 0 0" />
      <geometry>
        <mesh
          filename="package://blattoidea/meshes/r_caster_Link.STL" />
      </geometry>
      <material
        name="">
        <color
          rgba="0.898039215686275 0.917647058823529 0.929411764705882 1" />
      </material>
    </visual>
    <collision>
      <origin
        xyz="0 0 0"
        rpy="0 0 0" />
      <geometry>
        <mesh
          filename="package://blattoidea/meshes/r_caster_Link.STL" />
      </geometry>
    </collision>
  </link>
  <joint
    name="r_caster_joint"
    type="continuous">
    <origin
      xyz="-0.00200000000001023 0.00131343107405157 -0.0249654741355608"
      rpy="3.03621882782983 0.0974777924807896 3.13644802921112" />
    <parent
      link="rc_segment_Link" />
    <child
      link="r_caster_Link" />
    <axis
      xyz="0 0.99861896542272 0.052537242962078" />
  </joint>
  <link
    name="rc_wheel_Link">
    <inertial>
      <origin
        xyz="1.84574577843932E-14 -5.76969028109886E-14 7.27196081129478E-15"
        rpy="0 0 0" />
      <mass
        value="0.0498995656286701" />
      <inertia
        ixx="3.5408269639804E-05"
        ixy="5.96020113711229E-23"
        ixz="-1.24164310314982E-22"
        iyy="1.84620775423207E-05"
        iyz="-1.8355998794623E-21"
        izz="1.84620775423207E-05" />
    </inertial>
    <visual>
      <origin
        xyz="0 0 0"
        rpy="0 0 0" />
      <geometry>
        <mesh
          filename="package://blattoidea/meshes/rc_wheel_Link.STL" />
      </geometry>
      <material
        name="">
        <color
          rgba="1 1 1 1" />
      </material>
    </visual>
    <collision>
      <origin
        xyz="0 0 0"
        rpy="0 0 0" />
      <geometry>
        <mesh
          filename="package://blattoidea/meshes/rc_wheel_Link.STL" />
      </geometry>
    </collision>
  </link>
  <joint
    name="rc_wheel_joint"
    type="continuous">
    <origin
      xyz="0 -0.0013134310740316 0.0249654741355853"
      rpy="-0.0525614415799654 0 3.14159265358979" />
    <parent
      link="r_caster_Link" />
    <child
      link="rc_wheel_Link" />
    <axis
      xyz="1 0 0" />
  </joint>
  <link
    name="lc_segment_Link">
    <inertial>
      <origin
        xyz="-0.00199999999996911 0.0507028605154611 -0.0223671012384277"
        rpy="0 0 0" />
      <mass
        value="0.0456806083099005" />
      <inertia
        ixx="1.69365480799051E-05"
        ixy="-2.61652032862427E-08"
        ixz="4.97343727280349E-07"
        iyy="2.84210040220916E-05"
        iyz="8.69198280165364E-07"
        izz="1.19451595992085E-05" />
    </inertial>
    <visual>
      <origin
        xyz="0 0 0"
        rpy="0 0 0" />
      <geometry>
        <mesh
          filename="package://blattoidea/meshes/lc_segment_Link.STL" />
      </geometry>
      <material
        name="">
        <color
          rgba="0.898039215686275 0.917647058823529 0.929411764705882 1" />
      </material>
    </visual>
    <collision>
      <origin
        xyz="0 0 0"
        rpy="0 0 0" />
      <geometry>
        <mesh
          filename="package://blattoidea/meshes/lc_segment_Link.STL" />
      </geometry>
    </collision>
  </link>
  <joint
    name="lc_segment_joint"
    type="fixed">
    <origin
      xyz="-0.184049370454713 0.135573068545923 -0.0529999999999954"
      rpy="1.51823488521493 0 -1.47318329844307" />
    <parent
      link="base_link" />
    <child
      link="lc_segment_Link" />
    <axis
      xyz="0 0 0" />
  </joint>
  <link
    name="l_caster_Link">
    <inertial>
      <origin
        xyz="-1.88672001910639E-08 0.0301165962341981 0.01544731142568"
        rpy="0 0 0" />
      <mass
        value="0.0264605949467886" />
      <inertia
        ixx="1.12179776898766E-05"
        ixy="3.27558775107431E-12"
        ixz="-1.14314611888054E-12"
        iyy="9.11782185184734E-06"
        iyz="2.51887439877831E-06"
        izz="1.08616620506511E-05" />
    </inertial>
    <visual>
      <origin
        xyz="0 0 0"
        rpy="0 0 0" />
      <geometry>
        <mesh
          filename="package://blattoidea/meshes/l_caster_Link.STL" />
      </geometry>
      <material
        name="">
        <color
          rgba="0.898039215686275 0.917647058823529 0.929411764705882 1" />
      </material>
    </visual>
    <collision>
      <origin
        xyz="0 0 0"
        rpy="0 0 0" />
      <geometry>
        <mesh
          filename="package://blattoidea/meshes/l_caster_Link.STL" />
      </geometry>
    </collision>
  </link>
  <joint
    name="l_caster_joint"
    type="continuous">
    <origin
      xyz="-0.00199999999996087 0.00131343107405134 -0.0249654741355564"
      rpy="0.00025094260002981 -0.0974777924807896 -0.00514462437867282" />
    <parent
      link="lc_segment_Link" />
    <child
      link="l_caster_Link" />
    <axis
      xyz="0 0.99861896542272 0.052537242962078" />
  </joint>
  <link
    name="lc_wheel_Link">
    <inertial>
      <origin
        xyz="1.79023462720806E-14 2.96013213940682E-14 -2.99760216648792E-15"
        rpy="0 0 0" />
      <mass
        value="0.0498995656286702" />
      <inertia
        ixx="3.5408269639804E-05"
        ixy="5.3766926472594E-22"
        ixz="-9.59706170050521E-22"
        iyy="1.84620775423207E-05"
        iyz="2.30363884891597E-21"
        izz="1.84620775423207E-05" />
    </inertial>
    <visual>
      <origin
        xyz="0 0 0"
        rpy="0 0 0" />
      <geometry>
        <mesh
          filename="package://blattoidea/meshes/lc_wheel_Link.STL" />
      </geometry>
      <material
        name="">
        <color
          rgba="1 1 1 1" />
      </material>
    </visual>
    <collision>
      <origin
        xyz="0 0 0"
        rpy="0 0 0" />
      <geometry>
        <mesh
          filename="package://blattoidea/meshes/lc_wheel_Link.STL" />
      </geometry>
    </collision>
  </link>
  <joint
    name="lc_wheel_joint"
    type="continuous">
    <origin
      xyz="0 -0.00131343107400735 0.0249654741355546"
      rpy="3.08903121200983 0 3.14159265358979" />
    <parent
      link="l_caster_Link" />
    <child
      link="lc_wheel_Link" />
    <axis
      xyz="-1 0 0" />
  </joint>
  
	<transmission name="l_tran">
		<type>transmission_interface/SimpleTransmission</type>
		<joint name="lw_joint">
			<hardwareInterface>hardware_interface/VelocityJointInterface</hardwareInterface>
		</joint>
		<actuator name="l_motor">
			<hardwareInterface>hardware_interface/VelocityJointInterface</hardwareInterface>
			<mechanicalReduction>1</mechanicalReduction>
		</actuator>
	</transmission>

	<transmission name="r_tran">
		<type>transmission_interface/SimpleTransmission</type>
		<joint name="rw_joint">
			<hardwareInterface>hardware_interface/VelocityJointInterface</hardwareInterface>
		</joint>
		<actuator name="r_motor">
			<hardwareInterface>hardware_interface/VelocityJointInterface</hardwareInterface>
			<mechanicalReduction>1</mechanicalReduction>
		</actuator>
	</transmission>
	
	<gazebo>
		<plugin name="differential_drive_controller" filename="libgazebo_ros_diff_drive.so">
			<alwaysOn>true</alwaysOn>
			<updateRate>10</updateRate>
			<leftJoint>lw_joint</leftJoint>
			<rightJoint>rw_joint</rightJoint>
			<wheelSeparation>0.34</wheelSeparation>
			<wheelDiameter>0.165</wheelDiameter>
			<torque>1.41</torque>
			<commandTopic>cmd_vel</commandTopic>
			<odometryTopic>odom</odometryTopic>
			<odometryFrame>odom</odometryFrame>
			<robotBaseFrame>base_link</robotBaseFrame>
			<publishWheelJointState>true</publishWheelJointState>
		</plugin>
	</gazebo>
	
	<joint name="base_camera_joint" type="fixed">
    <origin xyz="0.2 0 0.17" rpy="0 0 0" />
    <parent link="base_link" />
    <origin xyz="0 0 0" rpy="0 0 0" />
    <child link="camera_link" />
  </joint>

  <link name="camera_link">
    <inertial>
      <mass value="0.01" />
      <origin xyz="0 0 0" />
      <inertia ixx="0.001" ixy="0.0" ixz="0.0"
        iyy="0.001" iyz="0.0"
        izz="0.001" />
    </inertial>

    <visual>
      <origin xyz=" 0 0 0 " rpy="0 0 0" />
      <geometry>
        <mesh filename="package://blattoidea/meshes/kinect.dae"/>
      </geometry>
    </visual>

    <collision>
      <origin xyz="0.0 0.0 0.0" rpy="0 0 0" />
      <geometry>
        <box size="0.0730 .2760 0.0720"/>
      </geometry>
    </collision>

  </link>
  
  <joint name="camera_depth_joint" type="fixed">
    <origin xyz="0 0.011 0" rpy="0 0 0" />
    <parent link="camera_link" />
    <child link="camera_depth_frame" />
  </joint>

  <link name="camera_depth_frame">
    <inertial>
      <mass value="0.01" />
      <origin xyz="0 0 0" />
      <inertia ixx="0.001" ixy="0.0" ixz="0.0"
        iyy="0.001" iyz="0.0"
        izz="0.001" />
    </inertial>
  </link>

  <joint name="camera_depth_optical_joint" type="fixed">
    <origin xyz="0 0 0" rpy="-1.57 0 -1.57" />
    <parent link="camera_depth_frame" />
    <child link="camera_depth_optical_frame" />
  </joint>

  <link name="camera_depth_optical_frame">
    <inertial>
      <mass value="0.001" />
      <origin xyz="0 0 0" />
      <inertia ixx="0.0001" ixy="0.0" ixz="0.0"
        iyy="0.0001" iyz="0.0"
        izz="0.0001" />
    </inertial>
  </link>

  <joint name="camera_rgb_joint" type="fixed">
    <origin xyz="0 -0.012 0" rpy="0 0 0" />
    <parent link="camera_link" />
    <child link="camera_rgb_frame" />
  </joint>

  <link name="camera_rgb_frame">
    <inertial>
      <mass value="0.001" />
      <origin xyz="0 0 0" />
      <inertia ixx="0.0001" ixy="0.0" ixz="0.0"
        iyy="0.0001" iyz="0.0"
        izz="0.0001" />
    </inertial>
  </link>

  <joint name="camera_rgb_optical_joint" type="fixed">
    <origin xyz="0 0 0" rpy="-1.57 0 -1.57" />
    <parent link="camera_rgb_frame" />
    <child link="camera_rgb_optical_frame" />
  </joint>

  <link name="camera_rgb_optical_frame">
    <inertial>
      <mass value="0.001" />
      <origin xyz="0 0 0" />
      <inertia ixx="0.0001" ixy="0.0" ixz="0.0"
        iyy="0.0001" iyz="0.0"
        izz="0.0001" />
    </inertial>
  </link>
  
  <gazebo reference="camera_link">
  <sensor name="kinect" type="depth">
    <update_rate>20</update_rate>
    <camera>
      <horizontal_fov>1.047198</horizontal_fov>
      <image>
        <width>640</width>
        <height>480</height>
        <format>R8G8B8</format>
      </image>
      <clip>
        <near>0.05</near>
        <far>5</far>
      </clip>
    </camera>
    <plugin name="depth_controller" filename="libgazebo_ros_openni_kinect.so">
      <baseline>0.2</baseline>
      <alwaysOn>true</alwaysOn>
      <updateRate>1.0</updateRate>
      <cameraName>kinect_ir</cameraName>
      <imageTopicName>/kinect/color/image_raw</imageTopicName>
      <cameraInfoTopicName>/kinect/color/camera_info</cameraInfoTopicName>
      <depthImageTopicName>/kinect/depth/image_raw</depthImageTopicName>
      <depthImageInfoTopicName>/kinect/depth/camera_info</depthImageInfoTopicName>
      <pointCloudTopicName>/kinect/depth/points</pointCloudTopicName>
      <frameName>camera_link</frameName>
      <pointCloudCutoff>0.5</pointCloudCutoff>
      <pointCloudCutoffMax>3.0</pointCloudCutoffMax>
      <distortionK1>0.00000001</distortionK1>
      <distortionK2>0.00000001</distortionK2>
      <distortionK3>0.00000001</distortionK3>
      <distortionT1>0.00000001</distortionT1>
      <distortionT2>0.00000001</distortionT2>
      <CxPrime>0</CxPrime>
      <Cx>0</Cx>
      <Cy>0</Cy>
      <focalLength>0</focalLength>
      <hackBaseline>0</hackBaseline>
    </plugin>
  </sensor>
</gazebo>
	
</robot>
