<?xml version="1.0" encoding="utf-8"?>
<!-- This URDF was automatically created by SolidWorks to URDF Exporter! Originally created by Stephen Brawner (brawner@gmail.com) 
     Commit Version: 1.5.1-0-g916b5db  Build Version: 1.5.7152.31018
     For more information, please see http://wiki.ros.org/sw_urdf_exporter -->
<robot xmlns:xacro="http://www.ros.org/wiki/xacro" 
	name="blattoidea">
<link name="base_link" />
<joint name="base_link_to_chassis" type="fixed">
    <parent link="base_link"/>
    <child link="chassis"/>
  </joint>
  <link
    name="chassis">
    <inertial>
      <origin
        xyz="0.0045146 -5.164E-15 0.057846"
        rpy="0 0 0" />
      <mass
        value="3.1167" />
      <inertia
        ixx="0.019062"
        ixy="-7.8129E-14"
        ixz="-1.0872E-16"
        iyy="0.027663"
        iyz="-6.4246E-16"
        izz="0.046295" />
    </inertial>
    <visual>
      <origin
        xyz="0 0 0"
        rpy="0 0 0" />
      <geometry>
        <mesh
          filename="package://blattoidea/meshes/base_link.STL" />
      </geometry>
      <material
        name="">
        <color
          rgba="0.89804 0.91765 0.92941 1" />
      </material>
    </visual>
    <collision>
      <origin
        xyz="0 0 0"
        rpy="0 0 0" />
      <geometry>
        <mesh
          filename="package://blattoidea/meshes/base_link.STL" />
      </geometry>
    </collision>
  </link>
  <link
    name="lw_Link">
    <inertial>
      <origin
        xyz="0.080855 -1.8595E-13 -7.2809E-06"
        rpy="0 0 0" />
      <mass
        value="0.97717" />
      <inertia
        ixx="0.0027567"
        ixy="-1.0351E-14"
        ixz="-3.9098E-07"
        iyy="0.001617"
        iyz="4.5745E-16"
        izz="0.0016171" />
    </inertial>
    <visual>
      <origin
        xyz="0 0 0"
        rpy="0 0 0" />
      <geometry>
        <mesh
          filename="package://blattoidea/meshes/lw_Link.STL" />
      </geometry>
      <material
        name="">
        <color
          rgba="1 1 1 1" />
      </material>
    </visual>
    <collision>
      <origin
        xyz="0 0 0"
        rpy="0 0 0" />
      <geometry>
        <mesh
          filename="package://blattoidea/meshes/lw_Link.STL" />
      </geometry>
    </collision>
  </link>
  <joint
    name="lw_joint"
    type="continuous">
    <origin
      xyz="0.17114 0.1226 -0.006"
      rpy="-1.5708 0 1.5708" />
    <parent
      link="base_link" />
    <child
      link="lw_Link" />
    <axis
      xyz="1 0 0" />
  </joint>
  <link
    name="rw_Link">
    <inertial>
      <origin
        xyz="0.080855 2.7863E-14 -7.2809E-06"
        rpy="0 0 0" />
      <mass
        value="0.97717" />
      <inertia
        ixx="0.0027567"
        ixy="-1.035E-14"
        ixz="-3.9098E-07"
        iyy="0.001617"
        iyz="4.5874E-16"
        izz="0.0016171" />
    </inertial>
    <visual>
      <origin
        xyz="0 0 0"
        rpy="0 0 0" />
      <geometry>
        <mesh
          filename="package://blattoidea/meshes/rw_Link.STL" />
      </geometry>
      <material
        name="">
        <color
          rgba="1 1 1 1" />
      </material>
    </visual>
    <collision>
      <origin
        xyz="0 0 0"
        rpy="0 0 0" />
      <geometry>
        <mesh
          filename="package://blattoidea/meshes/rw_Link.STL" />
      </geometry>
    </collision>
  </link>
  <joint
    name="rw_joint"
    type="continuous">
    <origin
      xyz="0.17114 -0.1226 -0.006"
      rpy="1.5708 0 -1.5708" />
    <parent
      link="base_link" />
    <child
      link="rw_Link" />
    <axis
      xyz="-1 0 0" />
  </joint>
  <link
    name="r_caster_Link">
    <inertial>
      <origin
        xyz="-1.8867E-08 -0.017703 0.012932"
        rpy="0 0 0" />
      <mass
        value="0.026461" />
      <inertia
        ixx="1.1218E-05"
        ixy="3.2756E-12"
        ixz="-1.1431E-12"
        iyy="9.1178E-06"
        iyz="2.5189E-06"
        izz="1.0862E-05" />
    </inertial>
    <visual>
      <origin
        xyz="0 0 0"
        rpy="0 0 0" />
      <geometry>
        <mesh
          filename="package://blattoidea/meshes/r_caster_Link.STL" />
      </geometry>
      <material
        name="">
        <color
          rgba="0.89804 0.91765 0.92941 1" />
      </material>
    </visual>
    <collision>
      <origin
        xyz="0 0 0"
        rpy="0 0 0" />
      <geometry>
        <mesh
          filename="package://blattoidea/meshes/r_caster_Link.STL" />
      </geometry>
    </collision>
  </link>
  <joint
    name="r_caster_joint"
    type="continuous">
    <origin
      xyz="-0.15936 -0.14 -0.0051144"
      rpy="1.5182 0 -1.5708" />
    <parent
      link="base_link" />
    <child
      link="r_caster_Link" />
    <axis
      xyz="0 0.99862 0.052537" />
  </joint>
  <link
    name="rc_wheel_Link">
    <inertial>
      <origin
        xyz="2.8588E-14 -7.8992E-14 2.9227E-14"
        rpy="0 0 0" />
      <mass
        value="0.0499" />
      <inertia
        ixx="3.5408E-05"
        ixy="1.3756E-22"
        ixz="-9.8358E-23"
        iyy="1.8462E-05"
        iyz="-2.8196E-22"
        izz="1.8462E-05" />
    </inertial>
    <visual>
      <origin
        xyz="0 0 0"
        rpy="0 0 0" />
      <geometry>
        <mesh
          filename="package://blattoidea/meshes/rc_wheel_Link.STL" />
      </geometry>
      <material
        name="">
        <color
          rgba="1 1 1 1" />
      </material>
    </visual>
    <collision>
      <origin
        xyz="0 0 0"
        rpy="0 0 0" />
      <geometry>
        <mesh
          filename="package://blattoidea/meshes/rc_wheel_Link.STL" />
      </geometry>
    </collision>
  </link>
  <joint
    name="rc_wheel_joint"
    type="continuous">
    <origin
      xyz="0 -0.049133 0.02245"
      rpy="-0.052561 0 3.1416" />
    <parent
      link="r_caster_Link" />
    <child
      link="rc_wheel_Link" />
    <axis
      xyz="1 0 0" />
  </joint>
  <link
    name="l_caster_Link">
    <inertial>
      <origin
        xyz="-1.8867E-08 -0.017703 0.012932"
        rpy="0 0 0" />
      <mass
        value="0.026461" />
      <inertia
        ixx="1.1218E-05"
        ixy="3.2756E-12"
        ixz="-1.1431E-12"
        iyy="9.1178E-06"
        iyz="2.5189E-06"
        izz="1.0862E-05" />
    </inertial>
    <visual>
      <origin
        xyz="0 0 0"
        rpy="0 0 0" />
      <geometry>
        <mesh
          filename="package://blattoidea/meshes/l_caster_Link.STL" />
      </geometry>
      <material
        name="">
        <color
          rgba="0.89804 0.91765 0.92941 1" />
      </material>
    </visual>
    <collision>
      <origin
        xyz="0 0 0"
        rpy="0 0 0" />
      <geometry>
        <mesh
          filename="package://blattoidea/meshes/l_caster_Link.STL" />
      </geometry>
    </collision>
  </link>
  <joint
    name="l_caster_joint"
    type="continuous">
    <origin
      xyz="-0.15936 0.14 -0.0051144"
      rpy="1.5182 0 -1.5708" />
    <parent
      link="base_link" />
    <child
      link="l_caster_Link" />
    <axis
      xyz="0 0.99862 0.052537" />
  </joint>
  <link
    name="lc_wheel_Link">
    <inertial>
      <origin
        xyz="3.7886E-14 3.1898E-14 1.2351E-14"
        rpy="0 0 0" />
      <mass
        value="0.0499" />
      <inertia
        ixx="3.5408E-05"
        ixy="5.3767E-22"
        ixz="-9.5971E-22"
        iyy="1.8462E-05"
        iyz="2.3036E-21"
        izz="1.8462E-05" />
    </inertial>
    <visual>
      <origin
        xyz="0 0 0"
        rpy="0 0 0" />
      <geometry>
        <mesh
          filename="package://blattoidea/meshes/lc_wheel_Link.STL" />
      </geometry>
      <material
        name="">
        <color
          rgba="1 1 1 1" />
      </material>
    </visual>
    <collision>
      <origin
        xyz="0 0 0"
        rpy="0 0 0" />
      <geometry>
        <mesh
          filename="package://blattoidea/meshes/lc_wheel_Link.STL" />
      </geometry>
    </collision>
  </link>
  <joint
    name="lc_wheel_joint"
    type="continuous">
    <origin
      xyz="0 -0.049133 0.02245"
      rpy="3.089 0 3.1416" />
    <parent
      link="l_caster_Link" />
    <child
      link="lc_wheel_Link" />
    <axis
      xyz="-1 0 0" />
  </joint>	



<joint name="base_camera_joint" type="fixed">
				<axis xyz="1 0 0" />
				<origin xyz="0.17 0.0 0.17" rpy="0 0 0" />
				<parent link="base_link" />
				<child link="camera_link" />
			  </joint>

		<link name="camera_link">
			<inertial>
				<mass value="0.01" />
				<origin xyz="0 0 0" />
				<inertia ixx="0.001" ixy="0.0" ixz="0.0"
					iyy="0.001" iyz="0.0"
					izz="0.001" />
			</inertial>
				<visual>
				<origin xyz=" 0 0 0 " rpy="0 0 0" />
				<geometry>
					<mesh filename="package://blattoidea/meshes/kinect.dae"/>
				</geometry>
			</visual>
			<collision>
				<origin xyz="0.0 0.0 0.0" rpy="0 0 0" />
				<geometry>
					<box size="0.0730 .2760 0.0720"/>
				</geometry>
			</collision>
		</link>


		<joint name="camera_optical_joint" type="fixed">
			<origin xyz="0 0 0" rpy="-1.57 0 -1.57" />
			<parent link="camera_link" />
			<child link="camera_optical_frame" />
		</joint>

		<link name="camera_optical_frame"/>

		<gazebo reference="camera_optical_frame"/>
		



		<gazebo reference="camera_link">
			<sensor name="kinect" type="depth">
				<update_rate>30</update_rate>
				<camera>
					<horizontal_fov>1.047198</horizontal_fov>
					<image>
						<width>640</width>
						<height>480</height>
						<format>R8G8B8</format>
					</image>
					<clip>
						<near>0.05</near>
						<far>20</far>
					</clip>
				</camera>
				<plugin name="depth_controller" filename="libgazebo_ros_openni_kinect.so">
					<baseline>0.2</baseline>
					<alwaysOn>true</alwaysOn>
					<updateRate>30.0</updateRate>
					<cameraName>kinect_ir</cameraName>
					<imageTopicName>/kinect/color/image_raw</imageTopicName>
					<cameraInfoTopicName>/kinect/color/camera_info</cameraInfoTopicName>
					<depthImageTopicName>/kinect/depth/image_raw</depthImageTopicName>
					<depthImageInfoTopicName>/kinect/depth/camera_info</depthImageInfoTopicName>
					<pointCloudTopicName>/kinect/depth/points</pointCloudTopicName>
					<frameName>camera_optical_frame</frameName>
					<pointCloudCutoff>0.05</pointCloudCutoff>
					<pointCloudCutoffMax>20</pointCloudCutoffMax>
					<distortionK1>0.0</distortionK1>
					<distortionK2>0.0</distortionK2>
					<distortionK3>0.0</distortionK3>
					<distortionT1>0.0</distortionT1>
					<distortionT2>0.0</distortionT2>
					<CxPrime>0</CxPrime>
					<Cx>0</Cx>
					<Cy>0</Cy>
					<focalLength>0</focalLength>
					<hackBaseline>0</hackBaseline>
				</plugin>
			</sensor>
		</gazebo>
</robot>
